Workbook

Sheet Overview & Methodology
A1: Financial audit - final 27 measures, FY2021-FY2025
A3: Course: Introduction to Business Finance, IBA Karachi. Instructor: Dr. Noureen Ayaz. Group members / IDs: to be completed by students.
A4: Five companies: KOHC, LUCK, DGKC, MLCF and FCCL. Official audited standalone / unconsolidated accounts. Financial amounts are PKR million unless stated.
A6: CURRENT: 27 Scope, 27 Calculations, 27 Industry, 27 Published, Balance Practices, EV Inputs and Reconciliation Guide. These define and verify the final submission.
A7: PRESERVED EVIDENCE: PSX Prices, Share Basis, Corporate Actions, Price Evidence, source register, Input Review, Opening Balances and the complete forensic investigation.
A8: ARCHIVED: company ratio tables and Industry Comparison use the prior 33-measure model. Published Ratio Reconciliation, Ratio Verification, Full Audit Summary and Archived Methodology retain historical results. Do not use them as current headline calculations.
A10: Current controls: 675 company-year results, 135 sample means, 422 balance tests and 455 published observations. 437 published values are numerically reconstructed; 18 remain unreproduced. A fit does not establish an expressly disclosed issuer formula.
A11: Sample means give equal weight to available numeric observations, exclude n/m and show valid counts in 27 Industry. Signed negative source amounts remain preserved. Genuine zeros remain numeric.
A13: Common formula and balance decisions
A14: Average opening/closing total inventory and net trade receivables. Closing PPE including CWIP, total assets, common equity and invested capital. FY2020 audited openings retained.
A15: EBIT = pre-levy/pre-tax profit + expensed interest. Non-interest finance charges stay expenses. ROIC uses actual uncapped audited ETR. Cash equivalents follow audited component notes before borrowing netting and after restricted-cash exclusions.
A16: Debt ratio uses all liabilities. D/E and debt-to-capital use interest-bearing principal and leases. EV adds identified other financial claims and uses book debt as an explicit market-value approximation.
... A19: Final 27-measure definitions
A21: ID | B21: Category | C21: Measure | D21: Requirement | E21: Origin | F21: Formula | G21: Short method note | H21: Basis detail
A22: 1 | B22: Liquidity | C22: Current Ratio | D22: Mandatory | E22: Table 4.2 | F22: Current assets / Current liabilities | G22: Closing current assets and liabilities. | H22: Period/share basis
A23: 2 | B23: Liquidity | C23: Quick Ratio | D23: Mandatory | E23: Table 4.2 | F23: (Current assets - Inventory) / Current liabilities | G23: Stores and stock excluded from current assets. | H23: Period/share basis
A24: 3 | B24: Liquidity | C24: Cash Ratio | D24: Mandatory | E24: University guideline | F24: Cash and equivalents / Current liabilities | G24: Available cash equivalents; borrowings remain in liabilities. | H24: Period/share basis
A25: 4 | B25: Liquidity | C25: Net Working Capital | D25: Additional | E25: Class PPT | F25: Current assets - Current liabilities | G25: Closing balances; signed working capital retained. | H25: Period/share basis
A26: 5 | B26: Asset Management | C26: Inventory Turnover | D26: Mandatory | E26: Table 4.2 | F26: COGS / Average inventory | G26: Average opening and closing stores and stock. | H26: Average
A27: 6 | B27: Asset Management | C27: Receivables Turnover | D27: Additional | E27: Class PPT | F27: Sales / Average trade receivables | G27: Average opening and closing net trade receivables. | H27: Average
A28: 7 | B28: Asset Management | C28: Days Inventory Outstanding | D28: Additional | E28: Class PPT | F28: 365 / Inventory turnover | G28: Average inventory; 365 days used. | H28: Average
A29: 8 | B29: Asset Management | C29: Days Sales Outstanding | D29: Mandatory | E29: Table 4.2 | F29: Receivables / (Annual sales / 365) | G29: Average receivables; sales proxy; 365 days. | H29: Average
A30: 9 | B30: Asset Management | C30: Fixed Asset Turnover | D30: Mandatory | E30: Table 4.2 | F30: Sales / Net fixed assets | G30: Closing net PPE, including CWIP. | H30: Closing
A31: 10 | B31: Asset Management | C31: Total Asset Turnover | D31: Mandatory | E31: Table 4.2 | F31: Sales / Total assets | G31: Closing total assets used consistently. | H31: Closing
A32: 11 | B32: Debt Management | C32: Debt Ratio | D32: Mandatory | E32: University guideline | F32: Total liabilities / Total assets | G32: All liabilities, including operating payables. | H32: Closing
A33: 12 | B33: Debt Management | C33: Debt-to-Equity Ratio | D33: Mandatory | E33: University guideline | F33: Interest-bearing debt / Common equity | G33: Interest-bearing principal and leases only. | H33: Closing
... A48: 27 | B48: Market Value | C48: Enterprise Value/EBITDA | D48: Additional | E48: Table 4.2 | F48: Enterprise value / (EBIT + D&A) | G48: Book debt approximates market financing value. | H48: Period/share basis
A52: Grouped reconciliation explanations
A53: Inventory and receivables use opening/closing averages, including audited FY2020 openings for FY2021. Assets, net PPE, equity and invested capital use closing balances for every company. Company-published closing or average variants are reconstructed separately. An isolated numerical fit does not confirm an issuer policy.
A54: Inventory includes stores, spares and stock-in-trade. PPE includes CWIP. Cash includes only audited qualifying equivalents, excludes pledged balances, and is gross of borrowing netting. Debt ratio includes all liabilities; D/E and debt-to-capital use interest-bearing principal and leases. MLCF freight reclassification changes COGS and gross margin without changing operating profit.
A55: EBIT = profit before levy/tax + expensed interest. Other recognized income stays included. Non-interest finance charges stay expenses. TIE uses expensed interest, not cash paid. ROIC uses this EBIT, actual uncapped audited ETR and closing IBD + equity. LUCK published ROE is numerically reproduced using comprehensive income; this project consistently uses net income.
A56: Market ratios use official PSX closes at year-end or the last preceding trading day. KOHC split trading began 25-Aug-2025, after FY2025; its FY2025 price is not divided by five. LUCK split trading began 28-Apr-2025. EPS, DPS and share counts retain compatible bases. Some published ratios use different or unconfirmed prices, share denominators or tangible-asset definitions.
A57: 437 of 455 current published observations are numerically reconstructed; this does not prove expressly disclosed issuer formulas. Eight FCCL asset-turnover observations conflict with annual sales/assets and the same report DuPont table. Five FCCL P/E, three FCCL DSO, one FCCL FY2025 TIE and one DGKC FY2021 cash ratio have unconfirmed exact published bases. All 18 remain disclosed below.
A60: Reconciliation Guide lists the exact numerator, denominator, project result and published value for each remaining case, with source references and confirmation status. Forensic 63 and Forensic Tests preserve every previous investigation.
A62: Prior confirmed input corrections are retained: LUCK FY2020 deferred tax 5,167.561m (note24.2), and FY2021 D&A 4,309.413m including amortization10.653m. Historical source values remain in the archived input model.
A64: References: supplied Project Guidelines pp5-6; Brigham & Houston Chapter4 Table4.2; class Chapter04 slides2-8; original audited annual reports and PSX disclosures. Secondary investigative material remains internal and supplies no authoritative financial input.

Sheet Published Ratio Reconciliation
A1: ARCHIVED - original published-ratio reconstruction record
A2: 544 official-source observations; baseline 44 financial failures and 10 market failures retained in column K. Numeric reproduction and officially disclosed formulas remain distinct.
A4: Company | B4: Published measure | C4: FY | D4: Published | E4: Standardized | F4: Reconstruction | G4: Convention tested | H4: Numeric comparison | I4: Investigation finding | J4: Official report / page | K4: Prior status | L4: Finding category | M4: Std minus published | N4: Reconstruction minus published | O4: Precision | P4: Official-glossary diagnostic | Q4: Diagnostic finding (not a standardized formula)
A5: KOHC | B5: Current ratio | C5: FY2021 | D5: 1.3 | E5: =KOHC!D138 -> 1.3006447 | F5: =KOHC!D36/KOHC!D61 -> 1.3006447 | G5: Standard definition | H5: =IF(AND(ISNUMBER(D5),ISNUMBER(F5)),IF(ROUND(D5,O5)=ROUND(F5,O5),"Reproduced to precision","Unresolved published value"),"Not comparable") -> Reproduced to precision | I5: Tested the source-based convention shown in G against official published precision. Unmatched values remain unresolved; neither the standardized method nor the financial inputs were altered to force agreement. | J5: FY2025 AR p53 "Key financial data for the last six years" (per-share items split-adjusted 5:1) | K5: Agrees (same convention) | L5: Source comparison | M5: =IF(ISNUMBER(E5),E5-D5,"n/m") -> 0.00064466914 | N5: =IF(ISNUMBER(F5),F5-D5,"n/m") -> 0.00064466914 | O5: 2
A6: KOHC | B6: Current ratio | C6: FY2022 | D6: 1.87 | E6: =KOHC!E138 -> 1.8735085 | F6: =KOHC!E36/KOHC!E61 -> 1.8735085 | G6: Standard definition | H6: =IF(AND(ISNUMBER(D6),ISNUMBER(F6)),IF(ROUND(D6,O6)=ROUND(F6,O6),"Reproduced to precision","Unresolved published value"),"Not comparable") -> Reproduced to precision | I6: Tested the source-based convention shown in G against official published precision. Unmatched values remain unresolved; neither the standardized method nor the financial inputs were altered to force agreement. | J6: FY2025 AR p53 "Key financial data for the last six years" (per-share items split-adjusted 5:1) | K6: Agrees (same convention) | L6: Source comparison | M6: =IF(ISNUMBER(E6),E6-D6,"n/m") -> 0.0035085276 | N6: =IF(ISNUMBER(F6),F6-D6,"n/m") -> 0.0035085276 | O6: 2
A7: KOHC | B7: Current ratio | C7: FY2023 | D7: 2.31 | E7: =KOHC!F138 -> 2.3115705 | F7: =KOHC!F36/KOHC!F61 -> 2.3115705 | G7: Standard definition | H7: =IF(AND(ISNUMBER(D7),ISNUMBER(F7)),IF(ROUND(D7,O7)=ROUND(F7,O7),"Reproduced to precision","Unresolved published value"),"Not comparable") -> Reproduced to precision | I7: Tested the source-based convention shown in G against official published precision. Unmatched values remain unresolved; neither the standardized method nor the financial inputs were altered to force agreement. | J7: FY2025 AR p53 "Key financial data for the last six years" (per-share items split-adjusted 5:1) | K7: Agrees (same convention) | L7: Source comparison | M7: =IF(ISNUMBER(E7),E7-D7,"n/m") -> 0.0015705155 | N7: =IF(ISNUMBER(F7),F7-D7,"n/m") -> 0.0015705155 | O7: 2
A8: KOHC | B8: Current ratio | C8: FY2024 | D8: 2.9 | E8: =KOHC!G138 -> 2.9031591 | F8: =KOHC!G36/KOHC!G61 -> 2.9031591 | G8: Standard definition | H8: =IF(AND(ISNUMBER(D8),ISNUMBER(F8)),IF(ROUND(D8,O8)=ROUND(F8,O8),"Reproduced to precision","Unresolved published value"),"Not comparable") -> Reproduced to precision | I8: Tested the source-based convention shown in G against official published precision. Unmatched values remain unresolved; neither the standardized method nor the financial inputs were altered to force agreement. | J8: FY2025 AR p53 "Key financial data for the last six years" (per-share items split-adjusted 5:1) | K8: Agrees (same convention) | L8: Source comparison | M8: =IF(ISNUMBER(E8),E8-D8,"n/m") -> 0.003159053 | N8: =IF(ISNUMBER(F8),F8-D8,"n/m") -> 0.003159053 | O8: 2
A9: KOHC | B9: Current ratio | C9: FY2025 | D9: 3.31 | E9: =KOHC!H138 -> 3.3112487 | F9: =KOHC!H36/KOHC!H61 -> 3.3112487 | G9: Standard definition | H9: =IF(AND(ISNUMBER(D9),ISNUMBER(F9)),IF(ROUND(D9,O9)=ROUND(F9,O9),"Reproduced to precision","Unresolved published value"),"Not comparable") -> Reproduced to precision | I9: Tested the source-based convention shown in G against official published precision. Unmatched values remain unresolved; neither the standardized method nor the financial inputs were altered to force agreement. | J9: FY2025 AR p53 "Key financial data for the last six years" (per-share items split-adjusted 5:1) | K9: Agrees (same convention) | L9: Source comparison | M9: =IF(ISNUMBER(E9),E9-D9,"n/m") -> 0.0012486872 | N9: =IF(ISNUMBER(F9),F9-D9,"n/m") -> 0.0012486872 | O9: 2
A10: KOHC | B10: Quick ratio | C10: FY2021 | D10: 0.75 | E10: =KOHC!D139 -> 0.74816044 | F10: =(KOHC!D36-KOHC!D65)/KOHC!D61 -> 0.74816044 | G10: Standard definition | H10: =IF(AND(ISNUMBER(D10),ISNUMBER(F10)),IF(ROUND(D10,O10)=ROUND(F10,O10),"Reproduced to precision","Unresolved published value"),"Not comparable") -> Reproduced to precision | I10: Tested the source-based convention shown in G against official published precision. Unmatched values remain unresolved; neither the standardized method nor the financial inputs were altered to force agreement. | J10: FY2025 AR p53 "Key financial data for the last six years" (per-share items split-adjusted 5:1) | K10: Agrees (same convention) | L10: Source comparison | M10: =IF(ISNUMBER(E10),E10-D10,"n/m") -> -0.0018395614 | N10: =IF(ISNUMBER(F10),F10-D10,"n/m") -> -0.0018395614 | O10: 2
A11: KOHC | B11: Quick ratio | C11: FY2022 | D11: 1.28 | E11: =KOHC!E139 -> 1.275807 | F11: =(KOHC!E36-KOHC!E65)/KOHC!E61 -> 1.275807 | G11: Standard definition | H11: =IF(AND(ISNUMBER(D11),ISNUMBER(F11)),IF(ROUND(D11,O11)=ROUND(F11,O11),"Reproduced to precision","Unresolved published value"),"Not comparable") -> Reproduced to precision | I11: Tested the source-based convention shown in G against official published precision. Unmatched values remain unresolved; neither the standardized method nor the financial inputs were altered to force agreement. | J11: FY2025 AR p53 "Key financial data for the last six years" (per-share items split-adjusted 5:1) | K11: Agrees (same convention) | L11: Source comparison | M11: =IF(ISNUMBER(E11),E11-D11,"n/m") -> -0.004192989 | N11: =IF(ISNUMBER(F11),F11-D11,"n/m") -> -0.004192989 | O11: 2
A12: KOHC | B12: Quick ratio | C12: FY2023 | D12: 1.54 | E12: =KOHC!F139 -> 1.539211 | F12: =(KOHC!F36-KOHC!F65)/KOHC!F61 -> 1.539211 | G12: Standard definition | H12: =IF(AND(ISNUMBER(D12),ISNUMBER(F12)),IF(ROUND(D12,O12)=ROUND(F12,O12),"Reproduced to precision","Unresolved published value"),"Not comparable") -> Reproduced to precision | I12: Tested the source-based convention shown in G against official published precision. Unmatched values remain unresolved; neither the standardized method nor the financial inputs were altered to force agreement. | J12: FY2025 AR p53 "Key financial data for the last six years" (per-share items split-adjusted 5:1) | K12: Agrees (same convention) | L12: Source comparison | M12: =IF(ISNUMBER(E12),E12-D12,"n/m") -> -0.00078896994 | N12: =IF(ISNUMBER(F12),F12-D12,"n/m") -> -0.00078896994 | O12: 2
A13: KOHC | B13: Quick ratio | C13: FY2024 | D13: 2.22 | E13: =KOHC!G139 -> 2.2200593 | F13: =(KOHC!G36-KOHC!G65)/KOHC!G61 -> 2.2200593 | G13: Standard definition | H13: =IF(AND(ISNUMBER(D13),ISNUMBER(F13)),IF(ROUND(D13,O13)=ROUND(F13,O13),"Reproduced to precision","Unresolved published value"),"Not comparable") -> Reproduced to precision | I13: Tested the source-based convention shown in G against official published precision. Unmatched values remain unresolved; neither the standardized method nor the financial inputs were altered to force agreement. | J13: FY2025 AR p53 "Key financial data for the last six years" (per-share items split-adjusted 5:1) | K13: Agrees (same convention) | L13: Source comparison | M13: =IF(ISNUMBER(E13),E13-D13,"n/m") -> 5.9339921e-05 | N13: =IF(ISNUMBER(F13),F13-D13,"n/m") -> 5.9339921e-05 | O13: 2
A14: KOHC | B14: Quick ratio | C14: FY2025 | D14: 2.67 | E14: =KOHC!H139 -> 2.6677004 | F14: =(KOHC!H36-KOHC!H65)/KOHC!H61 -> 2.6677004 | G14: Standard definition | H14: =IF(AND(ISNUMBER(D14),ISNUMBER(F14)),IF(ROUND(D14,O14)=ROUND(F14,O14),"Reproduced to precision","Unresolved published value"),"Not comparable") -> Reproduced to precision | I14: Tested the source-based convention shown in G against official published precision. Unmatched values remain unresolved; neither the standardized method nor the financial inputs were altered to force agreement. | J14: FY2025 AR p53 "Key financial data for the last six years" (per-share items split-adjusted 5:1) | K14: Agrees (same convention) | L14: Source comparison | M14: =IF(ISNUMBER(E14),E14-D14,"n/m") -> -0.0022996216 | N14: =IF(ISNUMBER(F14),F14-D14,"n/m") -> -0.0022996216 | O14: 2
A15: KOHC | B15: Inventory turnover | C15: FY2021 | D15: 5.75 | E15: =KOHC!D144 -> 4.8570986 | F15: =KOHC!D84/KOHC!D65 -> 5.7504757 | G15: Sales / closing stores + stock | H15: =IF(AND(ISNUMBER(D15),ISNUMBER(F15)),IF(ROUND(D15,O15)=ROUND(F15,O15),"Reproduced to precision","Unresolved published value"),"Not comparable") -> Reproduced to precision | I15: All five values reproduce using sales / closing total inventory. The class formula remains COGS / average total inventory. This is a mathematical reconstruction using audited inputs; the report does not explicitly state the inventory-turnover formula. | J15: FY2025 AR p53 "Key financial data for the last six years" (per-share items split-adjusted 5:1) | K15: Not reproduced | L15: Published methodology difference (reconstructed) | M15: =IF(ISNUMBER(E15),E15-D15,"n/m") -> -0.8929014 | N15: =IF(ISNUMBER(F15),F15-D15,"n/m") -> 0.00047570459 | O15: 2
A16: KOHC | B16: Inventory turnover | C16: FY2022 | D16: 5.8 | E16: =KOHC!E144 -> 4.6811317 | F16: =KOHC!E84/KOHC!E65 -> 5.7973952 | G16: Sales / closing stores + stock | H16: =IF(AND(ISNUMBER(D16),ISNUMBER(F16)),IF(ROUND(D16,O16)=ROUND(F16,O16),"Reproduced to precision","Unresolved published value"),"Not comparable") -> Reproduced to precision | I16: All five values reproduce using sales / closing total inventory. The class formula remains COGS / average total inventory. This is a mathematical reconstruction using audited inputs; the report does not explicitly state the inventory-turnover formula. | J16: FY2025 AR p53 "Key financial data for the last six years" (per-share items split-adjusted 5:1) | K16: Not reproduced | L16: Published methodology difference (reconstructed) | M16: =IF(ISNUMBER(E16),E16-D16,"n/m") -> -1.1188683 | N16: =IF(ISNUMBER(F16),F16-D16,"n/m") -> -0.0026048458 | O16: 2
A17: KOHC | B17: Inventory turnover | C17: FY2023 | D17: 5.08 | E17: =KOHC!F144 -> 4.2753791 | F17: =KOHC!F84/KOHC!F65 -> 5.0838139 | G17: Sales / closing stores + stock | H17: =IF(AND(ISNUMBER(D17),ISNUMBER(F17)),IF(ROUND(D17,O17)=ROUND(F17,O17),"Reproduced to precision","Unresolved published value"),"Not comparable") -> Reproduced to precision | I17: All five values reproduce using sales / closing total inventory. The class formula remains COGS / average total inventory. This is a mathematical reconstruction using audited inputs; the report does not explicitly state the inventory-turnover formula. | J17: FY2025 AR p53 "Key financial data for the last six years" (per-share items split-adjusted 5:1) | K17: Not reproduced | L17: Published methodology difference (reconstructed) | M17: =IF(ISNUMBER(E17),E17-D17,"n/m") -> -0.80462086 | N17: =IF(ISNUMBER(F17),F17-D17,"n/m") -> 0.0038139352 | O17: 2
A18: KOHC | B18: Inventory turnover | C18: FY2024 | D18: 5.1 | E18: =KOHC!G144 -> 3.595737 | F18: =KOHC!G84/KOHC!G65 -> 5.0990363 | G18: Sales / closing stores + stock | H18: =IF(AND(ISNUMBER(D18),ISNUMBER(F18)),IF(ROUND(D18,O18)=ROUND(F18,O18),"Reproduced to precision","Unresolved published value"),"Not comparable") -> Reproduced to precision | I18: All five values reproduce using sales / closing total inventory. The class formula remains COGS / average total inventory. This is a mathematical reconstruction using audited inputs; the report does not explicitly state the inventory-turnover formula. | J18: FY2025 AR p53 "Key financial data for the last six years" (per-share items split-adjusted 5:1) | K18: Not reproduced | L18: Published methodology difference (reconstructed) | M18: =IF(ISNUMBER(E18),E18-D18,"n/m") -> -1.504263 | N18: =IF(ISNUMBER(F18),F18-D18,"n/m") -> -0.00096369444 | O18: 2
A19: KOHC | B19: Inventory turnover | C19: FY2025 | D19: 5 | E19: =KOHC!H144 -> 3.0248806 | F19: =KOHC!H84/KOHC!H65 -> 5.0015137 | G19: Sales / closing stores + stock | H19: =IF(AND(ISNUMBER(D19),ISNUMBER(F19)),IF(ROUND(D19,O19)=ROUND(F19,O19),"Reproduced to precision","Unresolved published value"),"Not comparable") -> Reproduced to precision | I19: All five values reproduce using sales / closing total inventory. The class formula remains COGS / average total inventory. This is a mathematical reconstruction using audited inputs; the report does not explicitly state the inventory-turnover formula. | J19: FY2025 AR p53 "Key financial data for the last six years" (per-share items split-adjusted 5:1) | K19: Not reproduced | L19: Published methodology difference (reconstructed) | M19: =IF(ISNUMBER(E19),E19-D19,"n/m") -> -1.9751194 | N19: =IF(ISNUMBER(F19),F19-D19,"n/m") -> 0.0015137158 | O19: 2
A20: KOHC | B20: Days in receivables | C20: FY2021 | D20: 14.92 | E20: =KOHC!D148 -> 11.21127 | F20: =365*KOHC!D32/KOHC!D84 -> 14.922758 | G20: 365 x closing trade debts / sales | H20: =IF(AND(ISNUMBER(D20),ISNUMBER(F20)),IF(ROUND(D20,O20)=ROUND(F20,O20),"Reproduced to precision","Unresolved published value"),"Not comparable") -> Reproduced to precision | I20: Tested the source-based convention shown in G against official published precision. Unmatched values remain unresolved; neither the standardized method nor the financial inputs were altered to force agreement. | J20: FY2025 AR p53 "Key financial data for the last six years" (per-share items split-adjusted 5:1) | K20: Reconciled (company convention) | L20: Source comparison | M20: =IF(ISNUMBER(E20),E20-D20,"n/m") -> -3.7087305 | N20: =IF(ISNUMBER(F20),F20-D20,"n/m") -> 0.0027580562 | O20: 2
A21: KOHC | B21: Days in receivables | C21: FY2022 | D21: 10.17 | E21: =KOHC!E148 -> 10.544725 | F21: =365*KOHC!E32/KOHC!E84 -> 10.169873 | G21: 365 x closing trade debts / sales | H21: =IF(AND(ISNUMBER(D21),ISNUMBER(F21)),IF(ROUND(D21,O21)=ROUND(F21,O21),"Reproduced to precision","Unresolved published value"),"Not comparable") -> Reproduced to precision | I21: Tested the source-based convention shown in G against official published precision. Unmatched values remain unresolved; neither the standardized method nor the financial inputs were altered to force agreement. | J21: FY2025 AR p53 "Key financial data for the last six years" (per-share items split-adjusted 5:1) | K21: Reconciled (company convention) | L21: Source comparison | M21: =IF(ISNUMBER(E21),E21-D21,"n/m") -> 0.37472548 | N21: =IF(ISNUMBER(F21),F21-D21,"n/m") -> -0.00012674429 | O21: 2
A22: KOHC | B22: Days in receivables | C22: FY2023 | D22: 11.31 | E22: =KOHC!F148 -> 9.9479554 | F22: =365*KOHC!F32/KOHC!F84 -> 11.30546 | G22: 365 x closing trade debts / sales | H22: =IF(AND(ISNUMBER(D22),ISNUMBER(F22)),IF(ROUND(D22,O22)=ROUND(F22,O22),"Reproduced to precision","Unresolved published value"),"Not comparable") -> Reproduced to precision | I22: Tested the source-based convention shown in G against official published precision. Unmatched values remain unresolved; neither the standardized method nor the financial inputs were altered to force agreement. | J22: FY2025 AR p53 "Key financial data for the last six years" (per-share items split-adjusted 5:1) | K22: Reconciled (company convention) | L22: Source comparison | M22: =IF(ISNUMBER(E22),E22-D22,"n/m") -> -1.3620446 | N22: =IF(ISNUMBER(F22),F22-D22,"n/m") -> -0.0045402495 | O22: 2
A23: KOHC | B23: Days in receivables | C23: FY2024 | D23: 19.93 | E23: =KOHC!G148 -> 15.657663 | F23: =365*KOHC!G32/KOHC!G84 -> 19.929753 | G23: 365 x closing trade debts / sales | H23: =IF(AND(ISNUMBER(D23),ISNUMBER(F23)),IF(ROUND(D23,O23)=ROUND(F23,O23),"Reproduced to precision","Unresolved published value"),"Not comparable") -> Reproduced to precision | I23: Tested the source-based convention shown in G against official published precision. Unmatched values remain unresolved; neither the standardized method nor the financial inputs were altered to force agreement. | J23: FY2025 AR p53 "Key financial data for the last six years" (per-share items split-adjusted 5:1) | K23: Reconciled (company convention) | L23: Source comparison | M23: =IF(ISNUMBER(E23),E23-D23,"n/m") -> -4.2723368 | N23: =IF(ISNUMBER(F23),F23-D23,"n/m") -> -0.00024662361 | O23: 2
A24: KOHC | B24: Days in receivables | C24: FY2025 | D24: 16.46 | E24: =KOHC!H148 -> 18.487733 | F24: =365*KOHC!H32/KOHC!H84 -> 16.455255 | G24: 365 x closing trade debts / sales | H24: =IF(AND(ISNUMBER(D24),ISNUMBER(F24)),IF(ROUND(D24,O24)=ROUND(F24,O24),"Reproduced to precision","Unresolved published value"),"Not comparable") -> Reproduced to precision | I24: Tested the source-based convention shown in G against official published precision. Unmatched values remain unresolved; neither the standardized method nor the financial inputs were altered to force agreement. | J24: FY2025 AR p53 "Key financial data for the last six years" (per-share items split-adjusted 5:1) | K24: Reconciled (company convention) | L24: Source comparison | M24: =IF(ISNUMBER(E24),E24-D24,"n/m") -> 2.0277327 | N24: =IF(ISNUMBER(F24),F24-D24,"n/m") -> -0.0047453342 | O24: 2
A25: KOHC | B25: Days in payables | C25: FY2021 | D25: 33.74 | E25: =KOHC!D149 -> 26.695664 | F25: =365/((-KOHC!D85)/(KOHC!D51+KOHC!D254)) -> 33.736941 | G25: COGS / closing (trade creditors + contractors bills) | H25: =IF(AND(ISNUMBER(D25),ISNUMBER(F25)),IF(ROUND(D25,O25)=ROUND(F25,O25),"Reproduced to precision","Unresolved published value"),"Not comparable") -> Reproduced to precision | I25: Official note 9 lists local creditors, import bills and contractors bills separately. Published series reproduces by including contractors bills and using the closing balance. Standardized supplier-payable measure excludes unallocated contractor/capital balances and uses average opening/closing balances. | J25: FY2025 AR p53 "Key financial data for the last six years" (per-share items split-adjusted 5:1) | K25: Not reproduced | L25: Published methodology difference (reconstructed) | M25: =IF(ISNUMBER(E25),E25-D25,"n/m") -> -7.0443356 | N25: =IF(ISNUMBER(F25),F25-D25,"n/m") -> -0.0030591072 | O25: 2
A26: KOHC | B26: Days in payables | C26: FY2022 | D26: 20.97 | E26: =KOHC!E149 -> 22.445127 | F26: =365/((-KOHC!E85)/(KOHC!E51+KOHC!E254)) -> 20.968252 | G26: COGS / closing (trade creditors + contractors bills) | H26: =IF(AND(ISNUMBER(D26),ISNUMBER(F26)),IF(ROUND(D26,O26)=ROUND(F26,O26),"Reproduced to precision","Unresolved published value"),"Not comparable") -> Reproduced to precision | I26: Official note 9 lists local creditors, import bills and contractors bills separately. Published series reproduces by including contractors bills and using the closing balance. Standardized supplier-payable measure excludes unallocated contractor/capital balances and uses average opening/closing balances. | J26: FY2025 AR p53 "Key financial data for the last six years" (per-share items split-adjusted 5:1) | K26: Not reproduced | L26: Published methodology difference (reconstructed) | M26: =IF(ISNUMBER(E26),E26-D26,"n/m") -> 1.4751272 | N26: =IF(ISNUMBER(F26),F26-D26,"n/m") -> -0.0017484526 | O26: 2
A27: KOHC | B27: Days in payables | C27: FY2023 | D27: 9.14 | E27: =KOHC!F149 -> 12.531625 | F27: =365/((-KOHC!F85)/(KOHC!F51+KOHC!F254)) -> 9.1383817 | G27: COGS / closing (trade creditors + contractors bills) | H27: =IF(AND(ISNUMBER(D27),ISNUMBER(F27)),IF(ROUND(D27,O27)=ROUND(F27,O27),"Reproduced to precision","Unresolved published value"),"Not comparable") -> Reproduced to precision | I27: Official note 9 lists local creditors, import bills and contractors bills separately. Published series reproduces by including contractors bills and using the closing balance. Standardized supplier-payable measure excludes unallocated contractor/capital balances and uses average opening/closing balances. | J27: FY2025 AR p53 "Key financial data for the last six years" (per-share items split-adjusted 5:1) | K27: Not reproduced | L27: Published methodology difference (reconstructed) | M27: =IF(ISNUMBER(E27),E27-D27,"n/m") -> 3.3916247 | N27: =IF(ISNUMBER(F27),F27-D27,"n/m") -> -0.0016183424 | O27: 2
A28: KOHC | B28: Days in payables | C28: FY2024 | D28: 24.36 | E28: =KOHC!G149 -> 16.364411 | F28: =365/((-KOHC!G85)/(KOHC!G51+KOHC!G254)) -> 24.357241 | G28: COGS / closing (trade creditors + contractors bills) | H28: =IF(AND(ISNUMBER(D28),ISNUMBER(F28)),IF(ROUND(D28,O28)=ROUND(F28,O28),"Reproduced to precision","Unresolved published value"),"Not comparable") -> Reproduced to precision | I28: Official note 9 lists local creditors, import bills and contractors bills separately. Published series reproduces by including contractors bills and using the closing balance. Standardized supplier-payable measure excludes unallocated contractor/capital balances and uses average opening/closing balances. | J28: FY2025 AR p53 "Key financial data for the last six years" (per-share items split-adjusted 5:1) | K28: Not reproduced | L28: Published methodology difference (reconstructed) | M28: =IF(ISNUMBER(E28),E28-D28,"n/m") -> -7.9955888 | N28: =IF(ISNUMBER(F28),F28-D28,"n/m") -> -0.0027591544 | O28: 2
A29: KOHC | B29: Days in payables | C29: FY2025 | D29: 34.79 | E29: =KOHC!H149 -> 31.106489 | F29: =365/((-KOHC!H85)/(KOHC!H51+KOHC!H254)) -> 34.78887 | G29: COGS / closing (trade creditors + contractors bills) | H29: =IF(AND(ISNUMBER(D29),ISNUMBER(F29)),IF(ROUND(D29,O29)=ROUND(F29,O29),"Reproduced to precision","Unresolved published value"),"Not comparable") -> Reproduced to precision | I29: Official note 9 lists local creditors, import bills and contractors bills separately. Published series reproduces by including contractors bills and using the closing balance. Standardized supplier-payable measure excludes unallocated contractor/capital balances and uses average opening/closing balances. | J29: FY2025 AR p53 "Key financial data for the last six years" (per-share items split-adjusted 5:1) | K29: Not reproduced | L29: Published methodology difference (reconstructed) | M29: =IF(ISNUMBER(E29),E29-D29,"n/m") -> -3.6835111 | N29: =IF(ISNUMBER(F29),F29-D29,"n/m") -> -0.0011298098 | O29: 2
A30: KOHC | B30: Cash conversion cycle | C30: FY2021 | D30: 44.66 | E30: =KOHC!D151 -> 59.663349 | F30: =365*KOHC!D65/KOHC!D84+365*KOHC!D32/KOHC!D84-365*(KOHC!D51+KOHC!D254)/(-KOHC!D85) -> 44.658827 | G30: Company component conventions; independent raw reconstruction | H30: =IF(AND(ISNUMBER(D30),ISNUMBER(F30)),IF(ROUND(D30,O30)=ROUND(F30,O30),"Reproduced to precision","Unresolved published value"),"Not comparable") -> Reproduced to precision | I30: Tested the source-based convention shown in G against official published precision. Unmatched values remain unresolved; neither the standardized method nor the financial inputs were altered to force agreement. | J30: FY2025 AR p53 "Key financial data for the last six years" (per-share items split-adjusted 5:1) | K30: See components | L30: Source comparison | M30: =IF(ISNUMBER(E30),E30-D30,"n/m") -> 15.003349 | N30: =IF(ISNUMBER(F30),F30-D30,"n/m") -> -0.0011731675 | O30: 2
A31: KOHC | B31: Cash conversion cycle | C31: FY2022 | D31: 52.16 | E31: =KOHC!E151 -> 66.072196 | F31: =365*KOHC!E65/KOHC!E84+365*KOHC!E32/KOHC!E84-365*(KOHC!E51+KOHC!E254)/(-KOHC!E85) -> 52.160932 | G31: Company component conventions; independent raw reconstruction | H31: =IF(AND(ISNUMBER(D31),ISNUMBER(F31)),IF(ROUND(D31,O31)=ROUND(F31,O31),"Reproduced to precision","Unresolved published value"),"Not comparable") -> Reproduced to precision | I31: Tested the source-based convention shown in G against official published precision. Unmatched values remain unresolved; neither the standardized method nor the financial inputs were altered to force agreement. | J31: FY2025 AR p53 "Key financial data for the last six years" (per-share items split-adjusted 5:1) | K31: See components | L31: Source comparison | M31: =IF(ISNUMBER(E31),E31-D31,"n/m") -> 13.912196 | N31: =IF(ISNUMBER(F31),F31-D31,"n/m") -> 0.00093193202 | O31: 2
A32: KOHC | B32: Cash conversion cycle | C32: FY2023 | D32: 73.96 | E32: =KOHC!F151 -> 82.788876 | F32: =365*KOHC!F65/KOHC!F84+365*KOHC!F32/KOHC!F84-365*(KOHC!F51+KOHC!F254)/(-KOHC!F85) -> 73.963569 | G32: Company component conventions; independent raw reconstruction | H32: =IF(AND(ISNUMBER(D32),ISNUMBER(F32)),IF(ROUND(D32,O32)=ROUND(F32,O32),"Reproduced to precision","Unresolved published value"),"Not comparable") -> Reproduced to precision | I32: Tested the source-based convention shown in G against official published precision. Unmatched values remain unresolved; neither the standardized method nor the financial inputs were altered to force agreement. | J32: FY2025 AR p53 "Key financial data for the last six years" (per-share items split-adjusted 5:1) | K32: See components | L32: Source comparison | M32: =IF(ISNUMBER(E32),E32-D32,"n/m") -> 8.8288762 | N32: =IF(ISNUMBER(F32),F32-D32,"n/m") -> 0.0035688092 | O32: 2
A33: KOHC | B33: Cash conversion cycle | C33: FY2024 | D33: 67.15 | E33: =KOHC!G151 -> 100.80235 | F33: =365*KOHC!G65/KOHC!G84+365*KOHC!G32/KOHC!G84-365*(KOHC!G51+KOHC!G254)/(-KOHC!G85) -> 67.154666 | G33: Company component conventions; independent raw reconstruction | H33: =IF(AND(ISNUMBER(D33),ISNUMBER(F33)),IF(ROUND(D33,O33)=ROUND(F33,O33),"Reproduced to precision","Unresolved published value"),"Not comparable") -> Reproduced to precision | I33: Tested the source-based convention shown in G against official published precision. Unmatched values remain unresolved; neither the standardized method nor the financial inputs were altered to force agreement. | J33: FY2025 AR p53 "Key financial data for the last six years" (per-share items split-adjusted 5:1) | K33: See components | L33: Source comparison | M33: =IF(ISNUMBER(E33),E33-D33,"n/m") -> 33.652346 | N33: =IF(ISNUMBER(F33),F33-D33,"n/m") -> 0.0046661235 | O33: 2
A34: KOHC | B34: Cash conversion cycle | C34: FY2025 | D34: 54.64 | E34: =KOHC!H151 -> 108.04716 | F34: =365*KOHC!H65/KOHC!H84+365*KOHC!H32/KOHC!H84-365*(KOHC!H51+KOHC!H254)/(-KOHC!H85) -> 54.644291 | G34: Company component conventions; independent raw reconstruction | H34: =IF(AND(ISNUMBER(D34),ISNUMBER(F34)),IF(ROUND(D34,O34)=ROUND(F34,O34),"Reproduced to precision","Unresolved published value"),"Not comparable") -> Reproduced to precision | I34: Tested the source-based convention shown in G against official published precision. Unmatched values remain unresolved; neither the standardized method nor the financial inputs were altered to force agreement. | J34: FY2025 AR p53 "Key financial data for the last six years" (per-share items split-adjusted 5:1) | K34: See components | L34: Source comparison | M34: =IF(ISNUMBER(E34),E34-D34,"n/m") -> 53.407163 | N34: =IF(ISNUMBER(F34),F34-D34,"n/m") -> 0.0042909142 | O34: 2
A35: KOHC | B35: Total assets turnover | C35: FY2021 | D35: 0.67 | E35: =KOHC!D152 -> 0.70920116 | F35: =KOHC!D84/KOHC!D37 -> 0.66665083 | G35: Sales / closing assets | H35: =IF(AND(ISNUMBER(D35),ISNUMBER(F35)),IF(ROUND(D35,O35)=ROUND(F35,O35),"Reproduced to precision","Unresolved published value"),"Not comparable") -> Reproduced to precision | I35: Tested the source-based convention shown in G against official published precision. Unmatched values remain unresolved; neither the standardized method nor the financial inputs were altered to force agreement. | J35: FY2025 AR p53 "Key financial data for the last six years" (per-share items split-adjusted 5:1) | K35: Reconciled (company convention) | L35: Source comparison | M35: =IF(ISNUMBER(E35),E35-D35,"n/m") -> 0.039201162 | N35: =IF(ISNUMBER(F35),F35-D35,"n/m") -> -0.0033491738 | O35: 2
A36: KOHC | B36: Total assets turnover | C36: FY2022 | D36: 0.76 | E36: =KOHC!E152 -> 0.82774287 | F36: =KOHC!E84/KOHC!E37 -> 0.75839545 | G36: Sales / closing assets | H36: =IF(AND(ISNUMBER(D36),ISNUMBER(F36)),IF(ROUND(D36,O36)=ROUND(F36,O36),"Reproduced to precision","Unresolved published value"),"Not comparable") -> Reproduced to precision | I36: Tested the source-based convention shown in G against official published precision. Unmatched values remain unresolved; neither the standardized method nor the financial inputs were altered to force agreement. | J36: FY2025 AR p53 "Key financial data for the last six years" (per-share items split-adjusted 5:1) | K36: Reconciled (company convention) | L36: Source comparison | M36: =IF(ISNUMBER(E36),E36-D36,"n/m") -> 0.067742873 | N36: =IF(ISNUMBER(F36),F36-D36,"n/m") -> -0.0016045516 | O36: 2
A37: KOHC | B37: Total assets turnover | C37: FY2023 | D37: 0.79 | E37: =KOHC!F152 -> 0.83809914 | F37: =KOHC!F84/KOHC!F37 -> 0.78581821 | G37: Sales / closing assets | H37: =IF(AND(ISNUMBER(D37),ISNUMBER(F37)),IF(ROUND(D37,O37)=ROUND(F37,O37),"Reproduced to precision","Unresolved published value"),"Not comparable") -> Reproduced to precision | I37: Tested the source-based convention shown in G against official published precision. Unmatched values remain unresolved; neither the standardized method nor the financial inputs were altered to force agreement. | J37: FY2025 AR p53 "Key financial data for the last six years" (per-share items split-adjusted 5:1) | K37: Reconciled (company convention) | L37: Source comparison | M37: =IF(ISNUMBER(E37),E37-D37,"n/m") -> 0.048099135 | N37: =IF(ISNUMBER(F37),F37-D37,"n/m") -> -0.0041817891 | O37: 2
A38: KOHC | B38: Total assets turnover | C38: FY2024 | D38: 0.66 | E38: =KOHC!G152 -> 0.71323366 | F38: =KOHC!G84/KOHC!G37 -> 0.65679136 | G38: Sales / closing assets | H38: =IF(AND(ISNUMBER(D38),ISNUMBER(F38)),IF(ROUND(D38,O38)=ROUND(F38,O38),"Reproduced to precision","Unresolved published value"),"Not comparable") -> Reproduced to precision | I38: Tested the source-based convention shown in G against official published precision. Unmatched values remain unresolved; neither the standardized method nor the financial inputs were altered to force agreement. | J38: FY2025 AR p53 "Key financial data for the last six years" (per-share items split-adjusted 5:1) | K38: Reconciled (company convention) | L38: Source comparison | M38: =IF(ISNUMBER(E38),E38-D38,"n/m") -> 0.053233661 | N38: =IF(ISNUMBER(F38),F38-D38,"n/m") -> -0.0032086384 | O38: 2
A39: KOHC | B39: Total assets turnover | C39: FY2025 | D39: 0.56 | E39: =KOHC!H152 -> 0.59752333 | F39: =KOHC!H84/KOHC!H37 -> 0.56195953 | G39: Sales / closing assets | H39: =IF(AND(ISNUMBER(D39),ISNUMBER(F39)),IF(ROUND(D39,O39)=ROUND(F39,O39),"Reproduced to precision","Unresolved published value"),"Not comparable") -> Reproduced to precision | I39: Tested the source-based convention shown in G against official published precision. Unmatched values remain unresolved; neither the standardized method nor the financial inputs were altered to force agreement. | J39: FY2025 AR p53 "Key financial data for the last six years" (per-share items split-adjusted 5:1) | K39: Reconciled (company convention) | L39: Source comparison | M39: =IF(ISNUMBER(E39),E39-D39,"n/m") -> 0.037523326 | N39: =IF(ISNUMBER(F39),F39-D39,"n/m") -> 0.0019595349 | O39: 2
A40: KOHC | B40: Fixed assets turnover | C40: FY2021 | D40: 1.11 | E40: =KOHC!D153 -> 1.0844791 | F40: =KOHC!D84/KOHC!D22 -> 1.1059029 | G40: Sales / closing operating PPE | H40: =IF(AND(ISNUMBER(D40),ISNUMBER(F40)),IF(ROUND(D40,O40)=ROUND(F40,O40),"Reproduced to precision","Unresolved published value"),"Not comparable") -> Reproduced to precision | I40: Tested the source-based convention shown in G against official published precision. Unmatched values remain unresolved; neither the standardized method nor the financial inputs were altered to force agreement. | J40: FY2025 AR p53 "Key financial data for the last six years" (per-share items split-adjusted 5:1) | K40: Reconciled (company convention) | L40: Source comparison | M40: =IF(ISNUMBER(E40),E40-D40,"n/m") -> -0.025520899 | N40: =IF(ISNUMBER(F40),F40-D40,"n/m") -> -0.0040970657 | O40: 2
A41: KOHC | B41: Fixed assets turnover | C41: FY2022 | D41: 1.55 | E41: =KOHC!E153 -> 1.5307979 | F41: =KOHC!E84/KOHC!E22 -> 1.5507703 | G41: Sales / closing operating PPE | H41: =IF(AND(ISNUMBER(D41),ISNUMBER(F41)),IF(ROUND(D41,O41)=ROUND(F41,O41),"Reproduced to precision","Unresolved published value"),"Not comparable") -> Reproduced to precision | I41: Tested the source-based convention shown in G against official published precision. Unmatched values remain unresolved; neither the standardized method nor the financial inputs were altered to force agreement. | J41: FY2025 AR p53 "Key financial data for the last six years" (per-share items split-adjusted 5:1) | K41: Reconciled (company convention) | L41: Source comparison | M41: =IF(ISNUMBER(E41),E41-D41,"n/m") -> -0.01920211 | N41: =IF(ISNUMBER(F41),F41-D41,"n/m") -> 0.0007703457 | O41: 2
...

Sheet KOHC
A1: Kohat Cement Company Limited (KOHC) - five-year financial analysis, FY2021-FY2025
A2: Main company | PSX: KOHC | Standalone (single-entity financial statements; no consolidated statements published) | All amounts PKR million unless stated
A3: SOURCE INPUTS retained. Ratio tables below are ARCHIVED prior-33-measure workings; use 27 Calculations for final results. Blue = audited input; black = formula.
A5: A. COMPANY AND DATA INFORMATION
A6: Company | B6: Kohat Cement Company Limited
A7: PSX symbol | B7: KOHC
A8: Role in project | B8: Main company
A9: Financial year-end | B9: 30 June (FY2021 = year ended 30 June 2021, etc.)
A10: Reporting basis | B10: Standalone (single-entity financial statements; no consolidated statements published)
A11: Original audited units | B11: Rupees - normalised here to PKR million (full precision retained)
A12: Annual reports used | B12: FY2021: KOHC_AR_2021.pdf; FY2022: Kohat_Cement_AR_2022.pdf; FY2023: Financial_Statements-30-06-2023.pdf; FY2024: Kohat_Cement_Annual_Report-2024.pdf; FY2025: Kohat_Cement_Annual_Report_2025.pdf
A13: Year selection rule | B13: Each year taken from the most recent audited presentation: FY2025 from FY2025 AR; FY2020-FY2024 from the comparative column of the following year's AR (captures restatements). FY2020 = opening balances only.
A14: Per-share basis | B14: Actual PSX FY-end close paired with the share basis in force on that date. EPS notes, splits, treasury shares and bonus treatment are documented on Share Basis.
A15: Source register | B15: Every blue input is listed with report, statement, PDF page, printed page and remarks on the Sources & Validation sheet.
A17: Item | B17: Definition / formula / source note | C17: FY2020* | D17: FY2021 | E17: FY2022 | F17: FY2023 | G17: FY2024 | H17: FY2025 | I17: Units | J17: Comments
A18: B. STATEMENT OF FINANCIAL POSITION (PKR million; FY2020 = opening balances only)
A19: Non-current assets
A20: Property, plant and equipment (as presented) | B20: Input - see register KOHC|ppe | C20: 22777.666 | D20: 22027.545 | E20: 21331.296 | F20: 22229.434 | G20: 22156.641 | H20: 23359.981 | I20: PKR m
A21: of which: capital work-in-progress (note) | B21: Input - see register KOHC|cwip | C21: 164.57802 | D21: 273.93956 | E21: 130.89795 | F21: 1943.0196 | G21: 999.3266 | H21: 2486.6348 | I21: PKR m
A22: Operating fixed assets = PPE less CWIP | B22: PPE - CWIP | C22: =C20-C21 -> 22613.088 | D22: =D20-D21 -> 21753.605 | E22: =E20-E21 -> 21200.398 | F22: =F20-F21 -> 20286.415 | G22: =G20-G21 -> 21157.314 | H22: =H20-H21 -> 20873.346 | I22: PKR m
A23: Right-of-use assets (presented separately) | B23: Input - see register KOHC|rou | C23: 0 | D23: 0 | E23: 0 | F23: 0 | G23: 0 | H23: 0 | I23: PKR m
A24: Intangible assets | B24: Input - see register KOHC|intang | C24: 11.210982 | D24: 6.725911 | E24: 2.701357 | F24: 1.567709 | G24: 0.508226 | H24: 0.259742 | I24: PKR m
A25: Investment property | B25: Input - see register KOHC|inv_prop | C25: 3691.8396 | D25: 4134.0862 | E25: 4134.2552 | F25: 4324.9107 | G25: 4326.3616 | H25: 4326.3616 | I25: PKR m
A26: Long-term investments | B26: Input - see register KOHC|lt_inv | C26: 0 | D26: 0 | E26: 0 | F26: 0 | G26: 0 | H26: 0 | I26: PKR m
A27: Other non-current assets | B27: Input - see register KOHC|nca_other | C27: 38.32664 | D27: 69.76574 | E27: 106.58347 | F27: 60.785981 | G27: 147.38811 | H27: 492.91746 | I27: PKR m
A28: Total non-current assets | B28: Sum of above (excl. memo) | C28: =C20+C23+C24+C25+C26+C27 -> 26519.044 | D28: =D20+D23+D24+D25+D26+D27 -> 26238.123 | E28: =E20+E23+E24+E25+E26+E27 -> 25574.836 | F28: =F20+F23+F24+F25+F26+F27 -> 26616.699 | G28: =G20+G23+G24+G25+G26+G27 -> 26630.898 | H28: =H20+H23+H24+H25+H26+H27 -> 28179.519 | I28: PKR m
A29: Current assets
A30: Stores, spares and loose tools | B30: Input - see register KOHC|stores | C30: 2250.1564 | D30: 3070.7691 | E30: 4214.8296 | F30: 4713.1298 | G30: 5785.6835 | H30: 4991.3115 | I30: PKR m
A31: Stock-in-trade | B31: Input - see register KOHC|sit | C31: 1016.0242 | D31: 1112.7763 | E31: 1456.1568 | F31: 2942.8616 | G31: 1793.7424 | H31: 2513.5566 | I31: PKR m
A32: Trade debts | B32: Input - see register KOHC|debts | C32: 494.31521 | D32: 983.56822 | E32: 916.03947 | F32: 1205.5534 | G32: 2110.2479 | H32: 1692.2178 | I32: PKR m
A33: Short-term investments | B33: Input - see register KOHC|st_inv | C33: 160.1306 | D33: 2999.4964 | E33: 10124.096 | F33: 12335.074 | G33: 20279.746 | H33: 26941.632 | I33: PKR m
A34: Cash and bank balances | B34: Input - see register KOHC|cash | C34: 891.60609 | D34: 1197.7294 | E34: 480.76563 | F34: 933.53719 | G34: 1102.6492 | H34: 1450.7027 | I34: PKR m
A35: Other current assets | B35: Input - see register KOHC|ca_other | C35: 425.39123 | D35: 484.45935 | E35: 583.94424 | F35: 783.22095 | G35: 1140.3278 | H35: 1025.3717 | I35: PKR m
A36: Total current assets | B36: stores+sit+debts+st_inv+cash+ca_other | C36: =C30+C31+C32+C33+C34+C35 -> 5237.6238 | D36: =D30+D31+D32+D33+D34+D35 -> 9848.7987 | E36: =E30+E31+E32+E33+E34+E35 -> 17775.831 | F36: =F30+F31+F32+F33+F34+F35 -> 22913.377 | G36: =G30+G31+G32+G33+G34+G35 -> 32212.397 | H36: =H30+H31+H32+H33+H34+H35 -> 38614.792 | I36: PKR m
A37: TOTAL ASSETS | B37: tot_nca+tot_ca | C37: =C28+C36 -> 31756.667 | D37: =D28+D36 -> 36086.921 | E37: =E28+E36 -> 43350.668 | F37: =F28+F36 -> 49530.076 | G37: =G28+G36 -> 58843.295 | H37: =H28+H36 -> 66794.312 | I37: PKR m
A38: Equity
A39: Issued, subscribed and paid-up share capital | B39: Input - see register KOHC|share_cap | C39: 2008.613 | D39: 2008.613 | E39: 2008.613 | F39: 2008.613 | G39: 1958.613 | H39: 1838.613 | I39: PKR m
A40: Reserves, retained earnings and revaluation surplus | B40: Input - see register KOHC|eq_other | C40: 16718.06 | D40: 20214.926 | E40: 25237.607 | F40: 30601.432 | G40: 39131.692 | H40: 46116.582 | I40: PKR m
A41: Total equity | B41: share_cap+eq_other | C41: =C39+C40 -> 18726.673 | D41: =D39+D40 -> 22223.539 | E41: =E39+E40 -> 27246.22 | F41: =F39+F40 -> 32610.045 | G41: =G39+G40 -> 41090.305 | H41: =H39+H40 -> 47955.195 | I41: PKR m
A42: Non-current liabilities
...

Sheet LUCK
A1: Lucky Cement Limited (LUCK) - five-year financial analysis, FY2021-FY2025
A2: Competitor 1 | PSX: LUCK | Unconsolidated (separate) financial statements | All amounts PKR million unless stated
A3: SOURCE INPUTS retained. Ratio tables below are ARCHIVED prior-33-measure workings; use 27 Calculations for final results. Blue = audited input; black = formula.
A5: A. COMPANY AND DATA INFORMATION
A6: Company | B6: Lucky Cement Limited
A7: PSX symbol | B7: LUCK
A8: Role in project | B8: Competitor 1
A9: Financial year-end | B9: 30 June (FY2021 = year ended 30 June 2021, etc.)
A10: Reporting basis | B10: Unconsolidated (separate) financial statements
A11: Original audited units | B11: PKR '000 - normalised here to PKR million (full precision retained)
A12: Annual reports used | B12: FY2021: 2021.pdf; FY2022: 2022.pdf; FY2023: 2023.pdf; FY2024: 2024.pdf; FY2025: 2025.pdf
A13: Year selection rule | B13: Each year taken from the most recent audited presentation: FY2025 from FY2025 AR; FY2020-FY2024 from the comparative column of the following year's AR (captures restatements). FY2020 = opening balances only.
A14: Per-share basis | B14: Actual PSX FY-end close paired with the share basis in force on that date. EPS notes, splits, treasury shares and bonus treatment are documented on Share Basis.
A15: Source register | B15: Every blue input is listed with report, statement, PDF page, printed page and remarks on the Sources & Validation sheet.
A17: Item | B17: Definition / formula / source note | C17: FY2020* | D17: FY2021 | E17: FY2022 | F17: FY2023 | G17: FY2024 | H17: FY2025 | I17: Units | J17: Comments
A18: B. STATEMENT OF FINANCIAL POSITION (PKR million; FY2020 = opening balances only)
A19: Non-current assets
A20: Property, plant and equipment (as presented) | B20: Input - see register LUCK|ppe | C20: 60247.57 | D20: 62389.947 | E20: 82301.05 | F20: 95620.306 | G20: 107258.97 | H20: 107409.59 | I20: PKR m
A21: of which: capital work-in-progress (note) | B21: Input - see register LUCK|cwip | C21: 334.191 | D21: 4015.044 | E21: 21911.214 | F21: 5562.145 | G21: 11633.303 | H21: 5420.742 | I21: PKR m
A22: Operating fixed assets = PPE less CWIP | B22: PPE - CWIP | C22: =C20-C21 -> 59913.379 | D22: =D20-D21 -> 58374.903 | E22: =E20-E21 -> 60389.836 | F22: =F20-F21 -> 90058.161 | G22: =G20-G21 -> 95625.67 | H22: =H20-H21 -> 101988.85 | I22: PKR m
A23: Right-of-use assets (presented separately) | B23: Input - see register LUCK|rou | C23: 0 | D23: 0 | E23: 0 | F23: 0 | G23: 0 | H23: 0 | I23: PKR m
A24: Intangible assets | B24: Input - see register LUCK|intang | C24: 11.323 | D24: 0.67 | E24: 51.352 | F24: 85.588 | G24: 69.394 | H24: 46.229 | I24: PKR m
A25: Investment property | B25: Input - see register LUCK|inv_prop | C25: 0 | D25: 0 | E25: 0 | F25: 0 | G25: 0 | H25: 0 | I25: PKR m
A26: Long-term investments | B26: Input - see register LUCK|lt_inv | C26: 47144.485 | D26: 53194.485 | E26: 57594.485 | F26: 57594.485 | G26: 58072.373 | H26: 58555.707 | I26: PKR m
A27: Other non-current assets | B27: Input - see register LUCK|nca_other | C27: 90.183 | D27: 106.592 | E27: 199.79 | F27: 202.046 | G27: 165.266 | H27: 189.147 | I27: PKR m
A28: Total non-current assets | B28: Sum of above (excl. memo) | C28: =C20+C23+C24+C25+C26+C27 -> 107493.56 | D28: =D20+D23+D24+D25+D26+D27 -> 115691.69 | E28: =E20+E23+E24+E25+E26+E27 -> 140146.68 | F28: =F20+F23+F24+F25+F26+F27 -> 153502.43 | G28: =G20+G23+G24+G25+G26+G27 -> 165566.01 | H28: =H20+H23+H24+H25+H26+H27 -> 166200.67 | I28: PKR m
A29: Current assets
A30: Stores, spares and loose tools | B30: Input - see register LUCK|stores | C30: 6520.17 | D30: 10526.573 | E30: 11206.843 | F30: 14084.018 | G30: 14591.821 | H30: 19895.13 | I30: PKR m
A31: Stock-in-trade | B31: Input - see register LUCK|sit | C31: 2915.552 | D31: 3105.037 | E31: 7171.364 | F31: 6048.507 | G31: 8505.426 | H31: 4774.577 | I31: PKR m
A32: Trade debts | B32: Input - see register LUCK|debts | C32: 3422.767 | D32: 2710.081 | E32: 3522.931 | F32: 5089.667 | G32: 6932.479 | H32: 6353.194 | I32: PKR m
A33: Short-term investments | B33: Input - see register LUCK|st_inv | C33: 2970.999 | D33: 16227.103 | E33: 12751.155 | F33: 21898.496 | G33: 29837.628 | H33: 61298.052 | I33: PKR m
A34: Cash and bank balances | B34: Input - see register LUCK|cash | C34: 7816.606 | D34: 2825.424 | E34: 3871.078 | F34: 4116.181 | G34: 2567.176 | H34: 2790.323 | I34: PKR m
A35: Other current assets | B35: Input - see register LUCK|ca_other | C35: 4728.819 | D35: 5282.15 | E35: 6292.32 | F35: 8339.773 | G35: 6017.554 | H35: 5436.083 | I35: PKR m
A36: Total current assets | B36: stores+sit+debts+st_inv+cash+ca_other | C36: =C30+C31+C32+C33+C34+C35 -> 28374.913 | D36: =D30+D31+D32+D33+D34+D35 -> 40676.368 | E36: =E30+E31+E32+E33+E34+E35 -> 44815.691 | F36: =F30+F31+F32+F33+F34+F35 -> 59576.642 | G36: =G30+G31+G32+G33+G34+G35 -> 68452.084 | H36: =H30+H31+H32+H33+H34+H35 -> 100547.36 | I36: PKR m
A37: TOTAL ASSETS | B37: tot_nca+tot_ca | C37: =C28+C36 -> 135868.47 | D37: =D28+D36 -> 156368.06 | E37: =E28+E36 -> 184962.37 | F37: =F28+F36 -> 213079.07 | G37: =G28+G36 -> 234018.09 | H37: =H28+H36 -> 266748.03 | I37: PKR m
A38: Equity
A39: Issued, subscribed and paid-up share capital | B39: Input - see register LUCK|share_cap | C39: 3233.75 | D39: 3233.75 | E39: 3233.75 | F39: 3118.386 | G39: 2930 | H39: 2930 | I39: PKR m
A40: Reserves, retained earnings and revaluation surplus | B40: Input - see register LUCK|eq_other | C40: 95950.111 | D40: 109966.51 | E40: 125306.57 | F40: 134247.94 | G40: 144831.28 | H40: 172980.4 | I40: PKR m
A41: Total equity | B41: share_cap+eq_other | C41: =C39+C40 -> 99183.861 | D41: =D39+D40 -> 113200.26 | E41: =E39+E40 -> 128540.32 | F41: =F39+F40 -> 137366.33 | G41: =G39+G40 -> 147761.28 | H41: =H39+H40 -> 175910.4 | I41: PKR m
A42: Non-current liabilities
...

Sheet DGKC
A1: D.G. Khan Cement Company Limited (DGKC) - five-year financial analysis, FY2021-FY2025
A2: Competitor 2 | PSX: DGKC | Unconsolidated (separate) financial statements | All amounts PKR million unless stated
A3: SOURCE INPUTS retained. Ratio tables below are ARCHIVED prior-33-measure workings; use 27 Calculations for final results. Blue = audited input; black = formula.
A5: A. COMPANY AND DATA INFORMATION
A6: Company | B6: D.G. Khan Cement Company Limited
A7: PSX symbol | B7: DGKC
A8: Role in project | B8: Competitor 2
A9: Financial year-end | B9: 30 June (FY2021 = year ended 30 June 2021, etc.)
A10: Reporting basis | B10: Unconsolidated (separate) financial statements
A11: Original audited units | B11: Rs '000 - normalised here to PKR million (full precision retained)
A12: Annual reports used | B12: FY2021: DG_Annual_Report_2021.pdf; FY2022: DG_Annual_Report_2022.pdf; FY2023: DGAnnual2023.pdf; FY2024: DGAnnual2024.pdf; FY2025: DGAnnual2025.pdf
A13: Year selection rule | B13: Each year taken from the most recent audited presentation: FY2025 from FY2025 AR; FY2020-FY2024 from the comparative column of the following year's AR (captures restatements). FY2020 = opening balances only.
A14: Per-share basis | B14: Actual PSX FY-end close paired with the share basis in force on that date. EPS notes, splits, treasury shares and bonus treatment are documented on Share Basis.
A15: Source register | B15: Every blue input is listed with report, statement, PDF page, printed page and remarks on the Sources & Validation sheet.
A17: Item | B17: Definition / formula / source note | C17: FY2020* | D17: FY2021 | E17: FY2022 | F17: FY2023 | G17: FY2024 | H17: FY2025 | I17: Units | J17: Comments
A18: B. STATEMENT OF FINANCIAL POSITION (PKR million; FY2020 = opening balances only)
A19: Non-current assets
A20: Property, plant and equipment (as presented) | B20: Input - see register DGKC|ppe | C20: 83537.295 | D20: 85020.109 | E20: 82803.86 | F20: 82245.65 | G20: 79877.839 | H20: 77252.559 | I20: PKR m
A21: of which: capital work-in-progress (note) | B21: Input - see register DGKC|cwip | C21: 6358.259 | D21: 7726.72 | E21: 724.168 | F21: 2006.864 | G21: 1341.029 | H21: 798.312 | I21: PKR m
A22: Operating fixed assets = PPE less CWIP | B22: PPE - CWIP | C22: =C20-C21 -> 77179.036 | D22: =D20-D21 -> 77293.389 | E22: =E20-E21 -> 82079.692 | F22: =F20-F21 -> 80238.786 | G22: =G20-G21 -> 78536.81 | H22: =H20-H21 -> 76454.247 | I22: PKR m
A23: Right-of-use assets (presented separately) | B23: Input - see register DGKC|rou | C23: 0 | D23: 0 | E23: 0 | F23: 0 | G23: 0 | H23: 0 | I23: PKR m
A24: Intangible assets | B24: Input - see register DGKC|intang | C24: 0 | D24: 0 | E24: 17.319 | F24: 10.152 | G24: 42.762 | H24: 13.076 | I24: PKR m
A25: Investment property | B25: Input - see register DGKC|inv_prop | C25: 0 | D25: 0 | E25: 0 | F25: 0 | G25: 0 | H25: 0 | I25: PKR m
A26: Long-term investments | B26: Input - see register DGKC|lt_inv | C26: 11849.828 | D26: 15965.811 | E26: 12866.145 | F26: 13366.36 | G26: 16633.064 | H26: 20689.545 | I26: PKR m
A27: Other non-current assets | B27: Input - see register DGKC|nca_other | C27: 57.984 | D27: 57.513 | E27: 61.526 | F27: 64.426 | G27: 61.568 | H27: 61.013 | I27: PKR m
A28: Total non-current assets | B28: Sum of above (excl. memo) | C28: =C20+C23+C24+C25+C26+C27 -> 95445.107 | D28: =D20+D23+D24+D25+D26+D27 -> 101043.43 | E28: =E20+E23+E24+E25+E26+E27 -> 95748.85 | F28: =F20+F23+F24+F25+F26+F27 -> 95686.588 | G28: =G20+G23+G24+G25+G26+G27 -> 96615.233 | H28: =H20+H23+H24+H25+H26+H27 -> 98016.193 | I28: PKR m
A29: Current assets
A30: Stores, spares and loose tools | B30: Input - see register DGKC|stores | C30: 8237.99 | D30: 12879.348 | E30: 16813.883 | F30: 13852.005 | G30: 12559.774 | H30: 12306.679 | I30: PKR m
A31: Stock-in-trade | B31: Input - see register DGKC|sit | C31: 4352.995 | D31: 2728.589 | E31: 5981.515 | F31: 8873.17 | G31: 7693.067 | H31: 8188.678 | I31: PKR m
A32: Trade debts | B32: Input - see register DGKC|debts | C32: 2286.084 | D32: 1676.245 | E32: 1467.862 | F32: 1193.44 | G32: 855.742 | H32: 1493.08 | I32: PKR m
A33: Short-term investments | B33: Input - see register DGKC|st_inv | C33: 13126.388 | D33: 12946.786 | E33: 9962.421 | F33: 9270.898 | G33: 18384.882 | H33: 24005.1 | I33: PKR m
A34: Cash and bank balances | B34: Input - see register DGKC|cash | C34: 347.834 | D34: 806.373 | E34: 410.803 | F34: 674.972 | G34: 732.168 | H34: 568.832 | I34: PKR m
A35: Other current assets | B35: Input - see register DGKC|ca_other | C35: 5755.136 | D35: 5813.923 | E35: 6176.679 | F35: 5162.181 | G35: 1544.888 | H35: 1345.673 | I35: PKR m
A36: Total current assets | B36: stores+sit+debts+st_inv+cash+ca_other | C36: =C30+C31+C32+C33+C34+C35 -> 34106.427 | D36: =D30+D31+D32+D33+D34+D35 -> 36851.264 | E36: =E30+E31+E32+E33+E34+E35 -> 40813.163 | F36: =F30+F31+F32+F33+F34+F35 -> 39026.666 | G36: =G30+G31+G32+G33+G34+G35 -> 41770.521 | H36: =H30+H31+H32+H33+H34+H35 -> 47908.042 | I36: PKR m
A37: TOTAL ASSETS | B37: tot_nca+tot_ca | C37: =C28+C36 -> 129551.53 | D37: =D28+D36 -> 137894.7 | E37: =E28+E36 -> 136562.01 | F37: =F28+F36 -> 134713.25 | G37: =G28+G36 -> 138385.75 | H37: =H28+H36 -> 145924.23 | I37: PKR m
A38: Equity
A39: Issued, subscribed and paid-up share capital | B39: Input - see register DGKC|share_cap | C39: 4381.191 | D39: 4381.191 | E39: 4381.191 | F39: 4381.191 | G39: 4381.191 | H39: 4381.191 | I39: PKR m
A40: Reserves, retained earnings and revaluation surplus | B40: Input - see register DGKC|eq_other | C40: 62262.966 | D40: 69096.682 | E40: 65536.911 | F40: 59811.086 | G40: 71466.347 | H40: 90286.287 | I40: PKR m
A41: Total equity | B41: share_cap+eq_other | C41: =C39+C40 -> 66644.157 | D41: =D39+D40 -> 73477.873 | E41: =E39+E40 -> 69918.102 | F41: =F39+F40 -> 64192.277 | G41: =G39+G40 -> 75847.538 | H41: =H39+H40 -> 94667.478 | I41: PKR m
A42: Non-current liabilities
...

Sheet MLCF
A1: Maple Leaf Cement Factory Limited (MLCF) - five-year financial analysis, FY2021-FY2025
A2: Competitor 3 | PSX: MLCF | Unconsolidated (separate) financial statements | All amounts PKR million unless stated
A3: SOURCE INPUTS retained. Ratio tables below are ARCHIVED prior-33-measure workings; use 27 Calculations for final results. Blue = audited input; black = formula.
A5: A. COMPANY AND DATA INFORMATION
A6: Company | B6: Maple Leaf Cement Factory Limited
A7: PSX symbol | B7: MLCF
A8: Role in project | B8: Competitor 3
A9: Financial year-end | B9: 30 June (FY2021 = year ended 30 June 2021, etc.)
A10: Reporting basis | B10: Unconsolidated (separate) financial statements
A11: Original audited units | B11: Rs '000 - normalised here to PKR million (full precision retained)
A12: Annual reports used | B12: FY2021: 2021.pdf; FY2022: 2022.pdf; FY2023: 2023.pdf; FY2024: 2024.pdf; FY2025: 2025.pdf
